2023-05-09 08:36:29,931 INFO    StreamThr :18273 [internal.py:wandb_internal():86] W&B internal server running at pid: 18273, started at: 2023-05-09 08:36:29.931267
2023-05-09 08:36:29,932 DEBUG   HandlerThread:18273 [handler.py:handle_request():144] handle_request: status
2023-05-09 08:36:29,934 INFO    WriterThread:18273 [datastore.py:open_for_write():85] open: /home/bluesk/Documents/mate/wandb/run-20230509_083629-gm075ez4/run-gm075ez4.wandb
2023-05-09 08:36:29,934 DEBUG   SenderThread:18273 [sender.py:send():375] send: header
2023-05-09 08:36:29,935 DEBUG   SenderThread:18273 [sender.py:send():375] send: run
2023-05-09 08:36:33,174 INFO    SenderThread:18273 [retry.py:__call__():172] Retry attempt failed:
Traceback (most recent call last):
  File "/usr/lib/python3.11/site-packages/urllib3/connection.py", line 174, in _new_conn
    conn = connection.create_connection(
           ^^^^^^^^^^^^^^^^^^^^^^^^^^^^^
  File "/usr/lib/python3.11/site-packages/urllib3/util/connection.py", line 95, in create_connection
    raise err
  File "/usr/lib/python3.11/site-packages/urllib3/util/connection.py", line 85, in create_connection
    sock.connect(sa)
ConnectionRefusedError: [Errno 111] Connection refused

During handling of the above exception, another exception occurred:

Traceback (most recent call last):
  File "/usr/lib/python3.11/site-packages/urllib3/connectionpool.py", line 703, in urlopen
    httplib_response = self._make_request(
                       ^^^^^^^^^^^^^^^^^^^
  File "/usr/lib/python3.11/site-packages/urllib3/connectionpool.py", line 398, in _make_request
    conn.request(method, url, **httplib_request_kw)
  File "/usr/lib/python3.11/site-packages/urllib3/connection.py", line 244, in request
    super(HTTPConnection, self).request(method, url, body=body, headers=headers)
  File "/usr/lib/python3.11/http/client.py", line 1283, in request
    self._send_request(method, url, body, headers, encode_chunked)
  File "/usr/lib/python3.11/http/client.py", line 1329, in _send_request
    self.endheaders(body, encode_chunked=encode_chunked)
  File "/usr/lib/python3.11/http/client.py", line 1278, in endheaders
    self._send_output(message_body, encode_chunked=encode_chunked)
  File "/usr/lib/python3.11/http/client.py", line 1038, in _send_output
    self.send(msg)
  File "/usr/lib/python3.11/http/client.py", line 976, in send
    self.connect()
  File "/usr/lib/python3.11/site-packages/urllib3/connection.py", line 205, in connect
    conn = self._new_conn()
           ^^^^^^^^^^^^^^^^
  File "/usr/lib/python3.11/site-packages/urllib3/connection.py", line 186, in _new_conn
    raise NewConnectionError(
urllib3.exceptions.NewConnectionError: <urllib3.connection.HTTPConnection object at 0x7f3ef0282690>: Failed to establish a new connection: [Errno 111] Connection refused

During handling of the above exception, another exception occurred:

Traceback (most recent call last):
  File "/usr/lib/python3.11/site-packages/requests/adapters.py", line 489, in send
    resp = conn.urlopen(
           ^^^^^^^^^^^^^
  File "/usr/lib/python3.11/site-packages/urllib3/connectionpool.py", line 787, in urlopen
    retries = retries.increment(
              ^^^^^^^^^^^^^^^^^^
  File "/usr/lib/python3.11/site-packages/urllib3/util/retry.py", line 592, in increment
    raise MaxRetryError(_pool, url, error or ResponseError(cause))
urllib3.exceptions.MaxRetryError: HTTPConnectionPool(host='localhost', port=8080): Max retries exceeded with url: /graphql (Caused by NewConnectionError('<urllib3.connection.HTTPConnection object at 0x7f3ef0282690>: Failed to establish a new connection: [Errno 111] Connection refused'))

During handling of the above exception, another exception occurred:

Traceback (most recent call last):
  File "/home/bluesk/.local/lib/python3.11/site-packages/wandb/sdk/lib/retry.py", line 131, in __call__
    result = self._call_fn(*args, **kwargs)
             ^^^^^^^^^^^^^^^^^^^^^^^^^^^^^^
  File "/home/bluesk/.local/lib/python3.11/site-packages/wandb/sdk/internal/internal_api.py", line 285, in execute
    return self.client.execute(*args, **kwargs)  # type: ignore
           ^^^^^^^^^^^^^^^^^^^^^^^^^^^^^^^^^^^^
  File "/home/bluesk/.local/lib/python3.11/site-packages/wandb/vendor/gql-0.2.0/wandb_gql/client.py", line 52, in execute
    result = self._get_result(document, *args, **kwargs)
             ^^^^^^^^^^^^^^^^^^^^^^^^^^^^^^^^^^^^^^^^^^^
  File "/home/bluesk/.local/lib/python3.11/site-packages/wandb/vendor/gql-0.2.0/wandb_gql/client.py", line 60, in _get_result
    return self.transport.execute(document, *args, **kwargs)
           ^^^^^^^^^^^^^^^^^^^^^^^^^^^^^^^^^^^^^^^^^^^^^^^^^
  File "/home/bluesk/.local/lib/python3.11/site-packages/wandb/sdk/lib/gql_request.py", line 55, in execute
    request = self.session.post(self.url, **post_args)
              ^^^^^^^^^^^^^^^^^^^^^^^^^^^^^^^^^^^^^^^^
  File "/usr/lib/python3.11/site-packages/requests/sessions.py", line 635, in post
    return self.request("POST", url, data=data, json=json, **kwargs)
           ^^^^^^^^^^^^^^^^^^^^^^^^^^^^^^^^^^^^^^^^^^^^^^^^^^^^^^^^^
  File "/usr/lib/python3.11/site-packages/requests/sessions.py", line 587, in request
    resp = self.send(prep, **send_kwargs)
           ^^^^^^^^^^^^^^^^^^^^^^^^^^^^^^
  File "/usr/lib/python3.11/site-packages/requests/sessions.py", line 701, in send
    r = adapter.send(request, **kwargs)
        ^^^^^^^^^^^^^^^^^^^^^^^^^^^^^^^
  File "/usr/lib/python3.11/site-packages/requests/adapters.py", line 565, in send
    raise ConnectionError(e, request=request)
requests.exceptions.ConnectionError: HTTPConnectionPool(host='localhost', port=8080): Max retries exceeded with url: /graphql (Caused by NewConnectionError('<urllib3.connection.HTTPConnection object at 0x7f3ef0282690>: Failed to establish a new connection: [Errno 111] Connection refused'))
2023-05-09 08:36:34,936 DEBUG   HandlerThread:18273 [handler.py:handle_request():144] handle_request: keepalive
2023-05-09 08:36:39,937 DEBUG   HandlerThread:18273 [handler.py:handle_request():144] handle_request: keepalive
2023-05-09 08:36:44,939 DEBUG   HandlerThread:18273 [handler.py:handle_request():144] handle_request: keepalive
2023-05-09 08:36:49,940 DEBUG   HandlerThread:18273 [handler.py:handle_request():144] handle_request: keepalive
2023-05-09 08:36:54,941 DEBUG   HandlerThread:18273 [handler.py:handle_request():144] handle_request: keepalive
2023-05-09 08:36:59,943 DEBUG   HandlerThread:18273 [handler.py:handle_request():144] handle_request: keepalive
2023-05-09 08:37:04,944 DEBUG   HandlerThread:18273 [handler.py:handle_request():144] handle_request: keepalive
2023-05-09 08:37:09,946 DEBUG   HandlerThread:18273 [handler.py:handle_request():144] handle_request: keepalive
2023-05-09 08:37:14,947 DEBUG   HandlerThread:18273 [handler.py:handle_request():144] handle_request: keepalive
2023-05-09 08:37:21,881 DEBUG   HandlerThread:18273 [handler.py:handle_request():144] handle_request: shutdown
2023-05-09 08:37:21,881 INFO    HandlerThread:18273 [handler.py:finish():845] shutting down handler
2023-05-09 08:37:21,942 INFO    WriterThread:18273 [datastore.py:close():298] close: /home/bluesk/Documents/mate/wandb/run-20230509_083629-gm075ez4/run-gm075ez4.wandb
